Workbook
Name Slicer_Gender: #N/A
Name Slicer_Sub_Category: #N/A
Name Slicer_Years__Order_Date: #N/A

Sheet Customer_Raw
A1: Customer_ID | B1: Name | C1: Age | D1: Gender | E1: City | F1: State | G1: Country | H1: Loyalty_Level
A2: CUST1000 | B2: sheena bonilla | C2: 55 | D2: Male | E2: Donaldton | F2: North Carolina | G2: USA
A3: CUST1001 | B3: Eugene Nelson | C3: 26 | D3: Female | E3: Phillipsmouth | F3: North Dakota | G3: USA | H3: Platinum
A4: CUST1002 | B4: dr. Benjamin Price | C4: 29 | D4: Female | E4: Kylebury | F4: Alabama | G4: USA | H4: Platinum
A5: CUST1003 | B5: jeremy harris | C5: 59 | D5: Female | E5: Thomastown | F5: Ohio | G5: USA | H5: Bronze
A6: CUST1004 | B6: Caroline Collins | C6: 64 | D6: Female | E6: Nicholasshire | F6: California | G6: USA | H6: Silver
A7: CUST1005 | B7: Christine Vaughn | C7: 24 | D7: Male | E7: East Amandamouth | F7: Oregon | G7: USA | H7: Bronze
A8: CUST1006 | B8: Amber Jackson | C8: 29 | D8: Female | E8: Deborahborough | F8: South Dakota | G8: USA | H8: Platinum
A9: CUST1007 | B9: Daniel Boyd | C9: 29 | D9: Female | E9: West Pamelafurt | F9: West Virginia | G9: USA | H9: Bronze
A10: CUST1008 | B10: Melissa Howard | C10: 53 | D10: Female | E10: Maynardton | F10: New Hampshire | G10: USA | H10: Gold
A11: CUST1009 | B11: Ms. Maria Leach | C11: 64 | D11: Male | E11: Melissashire | F11: Pennsylvania | G11: USA | H11: Platinum
A12: CUST1010 | B12: Dominic Page | C12: 53 | D12: Male | E12: Port Michaelburgh | F12: Pennsylvania | G12: USA | H12: Bronze
A13: CUST1011 | B13: Brian Lopez | C13: 28 | D13: Female | E13: East Krista | F13: New York | G13: USA | H13: Gold
A14: CUST1012 | B14: Kenneth Lambert | C14: 55 | D14: Female | E14: North Kathryn | F14: Kansas | G14: USA | H14: Platinum
... A19: CUST1017 | B19: Adam Cruz | C19: 60 | D19: Female | E19: Brandonville | F19: Georgia | G19: USA | H19: Platinum
A20: CUST1018 | B20: Rhonda Moss | C20: 43 | D20: Male | E20: South William | F20: Kansas | G20: USA
A21: CUST1019 | B21: Michael Torres | C21: 46 | D21: Female | E21: Gonzalezfort | F21: New Jersey | G21: USA | H21: Platinum
A22: CUST1020 | B22: Bridget Allen | C22: 59 | D22: Male | E22: Lake Shaneburgh | F22: Delaware | G22: USA | H22: Silver
A23: CUST1021 | B23: Jeff Martinez | C23: 36 | D23: Female | E23: Smithburgh | F23: Oklahoma | G23: USA | H23: Gold
A24: CUST1022 | B24: paul fox | C24: 33 | D24: Female | E24: Michaelton | F24: Hawaii | G24: USA | H24: Silver
A25: CUST1023 | B25: Jonathan Steele | C25: 52 | D25: Female | E25: Molinabury | F25: Oregon | G25: USA | H25: Silver
A26: CUST1024 | B26: Heather Collins | C26: 40 | D26: Male | E26: Rogerschester | F26: Idaho | G26: USA | H26: Platinum
A27: CUST1025 | B27: Diana Taylor | C27: 59 | D27: Female | E27: Vasqueztown | F27: California | G27: USA | H27: Bronze
A28: CUST1026 | B28: Amber Carlson | C28: 18 | D28: Female | E28: East Michellemouth | F28: Missouri | G28: USA | H28: Gold
A29: CUST1027 | B29: Leslie Johnson | C29: 31 | D29: Male | E29: Mollyshire | F29: Utah | G29: USA
A30: CUST1028 | B30: Joshua Ryan | C30: 27 | D30: Female | E30: New David | F30: New Jersey | G30: USA | H30: Platinum
A31: CUST1029 | B31: David Arnold | C31: 54 | D31: Female | E31: East Jennifer | F31: California | G31: USA | H31: Silver
A32: CUST1030 | B32: Jessica Acevedo | C32: 64 | D32: Female | E32: Amybury | F32: Pennsylvania | G32: USA | H32: Bronze
A33: CUST1031 | B33: Sarah Vance | C33: 41 | D33: Male | E33: Johnsonville | F33: Oregon | G33: USA | H33: Silver
A34: CUST1032 | B34: Mike Jennings | C34: 48 | D34: Female | E34: Fostermouth | F34: Arizona | G34: USA | H34: Gold
A35: CUST1033 | B35: Robert Jones DDS | C35: 25 | D35: Male | E35: Tristanton | F35: Oklahoma | G35: USA | H35: Platinum
A36: CUST1034 | B36: Christopher Olson | C36: 27 | D36: Female | E36: West Richard | F36: Maryland | G36: USA | H36: Platinum
A37: CUST1035 | B37: Rachel Myers | C37: 52 | D37: Male | E37: Robertberg | F37: North Dakota | G37: USA | H37: Silver
A38: CUST1036 | B38: Thomas Phillips | C38: 20 | D38: Female | E38: Luisfurt | F38: Georgia | G38: USA | H38: Gold
A39: CUST1037 | B39: Christopher Carter | C39: 27 | D39: Female | E39: Brendastad | F39: South Dakota | G39: USA
A40: CUST1038 | B40: Deanna Simpson | C40: 35 | D40: Female | E40: Brownport | F40: North Dakota | G40: USA | H40: Bronze
A41: CUST1039 | B41: Tonya Reynolds | C41: 55 | D41: Female | E41: Darleneton | F41: Michigan | G41: USA | H41: Gold
A42: CUST1040 | B42: Eric Vega | C42: 50 | D42: Male | E42: Williamsonland | F42: Kansas | G42: USA | H42: Gold
A43: CUST1041 | B43: James Gibbs | C43: 21 | D43: Male | E43: Mooneyshire | F43: Alaska | G43: USA | H43: Platinum
A44: CUST1042 | B44: William Martin | C44: 19 | D44: Male | E44: Ryanburgh | F44: Connecticut | G44: USA | H44: Platinum
...

Sheet Product_Raw
A1: Product_ID | B1: Product_Name | C1: Category | D1: Sub_Category | E1: Brand | F1: COST ORI | G1: Stock ORI | H1: Stock
A2: PROD0 | B2: Brother Laser Printer | C2: Electronics | D2: Computer | E2: Hunt Inc | F2: 112 | G2: 416 | H2: 416
A3: PROD1 | B3: Men's Graphic T-Shirt | C3: Clothing | D3: Tops | E3: Terry-Moore | F3: 342 | G3: 181 | H3: 181
A4: PROD2 | B4: Women's Casual Hoodie | C4: Clothing | D4: Outerwear | E4: Sims Inc | F4: 254 | G4: 352 | H4: 352
A5: PROD3 | B5: Men's Running Jacket | C5: Clothing | D5: Outerwear | E5: Pineda Ltd | F5: 364 | G5: 452 | H5: 452
A6: PROD4 | B6: Women's Yoga Pants | C6: Clothing | D6: Bottoms | E6: Gonzales-Davis | F6: 306 | G6: 487 | H6: 487
A7: PROD5 | B7: Men's Leather Belt | C7: Clothing | D7: Accessories | E7: Baldwin, Garza and Gonzalez | F7: 261 | G7: 59 | H7: 59
A8: PROD6 | B8: Herbal Face Moisturizer | C8: Beauty | D8: Skincare | E8: Davidson PLC | F8: 312 | G8: 343 | H8: 350
A9: PROD7 | B9: LED Table Lamp | C9: Home | D9: Lighting | E9: Harrell LLC | F9: 218 | G9: 360 | H9: 170
A10: PROD8 | B10: Wireless Bluetooth Earbuds | C10: Electronics | D10: Audio | E10: Perez-Johnston | F10: 439 | G10: 268 | H10: 142
A11: PROD9 | B11: Adjustable Dumbbell Set | C11: Sports | D11: Fitness | E11: Hill PLC | F11: 495 | G11: 154 | H11: 323
A12: PROD10 | B12: Ceramic Kitchen Bowl Set | C12: Home | D12: Kitchen | E12: Hamilton Group | F12: 298 | G12: 214 | H12: 308
A13: PROD11 | B13: HD Smart TV Stick | C13: Electronics | D13: Accessories | E13: Gibson, Hobbs and Weaver | F13: 449 | G13: 296 | H13: 296
A14: PROD12 | B14: Hair Strengthening Shampoo | C14: Beauty | D14: Haircare | E14: Rice LLC | F14: 115 | G14: 125 | H14: 460
A15: PROD13 | B15: USB-C Fast Charger | C15: Electronics | D15: Accessories | E15: Dawson-Perkins | F15: 242 | G15: 485 | H15: 453
A16: PROD14 | B16: Decorative Wall Mirror | C16: Home | D16: Decor | E16: Luna, Anderson and Bowman | F16: 48 | G16: 224 | H16: 439
A17: PROD15 | B17: 4K Home Projector | C17: Electronics | D17: Appliances | E17: Thomas LLC | F17: 465 | G17: 82 | H17: 301
A18: PROD16 | B18: Beard Grooming Kit | C18: Beauty | D18: Grooming | E18: Erickson-Green | F18: 337 | G18: 210 | H18: 256
A19: PROD17 | B19: Soccer Training Cone Set | C19: Sports | D19: Accessories | E19: Ford, Murphy and Wilson | F19: 144 | G19: 496 | H19: 367
A20: PROD18 | B20: Women's Denim Jeans | C20: Clothing | D20: Bottoms | E20: Guerra-Hendrix | F20: 254 | G20: 343 | H20: 343
A21: PROD19 | B21: Knee Support Brace | C21: Sports | D21: Equipment | E21: May-Reese | F21: 21 | G21: 65 | H21: 65
A22: PROD20 | B22: Outdoor Sports Water Bottle | C22: Sports | D22: Accessories | E22: Soto-Ellis | F22: 131 | G22: 268 | H22: =INT(IF(ISBLANK(I22),AVERAGE($H22:$H$99),I22)) -> 268
A23: PROD21 | B23: Multi-Purpose Storage Box | C23: Home | D23: Storage | E23: Gardner-Montes | F23: 123 | G23: 76 | H23: 76
A24: PROD22 | B24: Carbon Fiber Tennis Racket | C24: Sports | D24: Equipment | E24: Flores, Pineda and Rodriguez | F24: 484 | G24: 432 | H24: 432
A25: PROD23 | B25: Men's Formal Shirt | C25: Clothing | D25: Tops | E25: Moon, Mora and Santos | F25: 254 | G25: 360 | H25: 360
A26: PROD24 | B26: Foldable Camping Chair | C26: Sports | D26: Outdoor | E26: Cook Ltd | F26: 166 | G26: 340 | H26: 340
A27: PROD25 | B27: Women's Scarf Set | C27: Clothing | D27: Accessories | E27: Brown and Sons | F27: 174 | G27: 268 | H27: 268
A28: PROD26 | B28: Wireless Bluetooth Speaker | C28: Electronics | D28: Audio | E28: Reed-Schmidt | F28: 322 | G28: 213 | H28: 213
A29: PROD27 | B29: Decorative Floor Vase | C29: Home | D29: Decor | E29: Khan, Jones and Paul | F29: 254 | G29: 378 | H29: 378
A30: PROD28 | B30: Sports Stopwatch Timer | C30: Sports | D30: Accessories | E30: Burns-Hansen | F30: 38 | G30: 137 | H30: 137
A31: PROD29 | B31: Fabric Sofa Throw Blanket | C31: Home | D31: Decor | E31: Hoffman Group | F31: 218 | G31: 276 | H31: 276
A32: PROD30 | B32: Stainless Steel Cutlery Set | C32: Home | D32: Kitchen | E32: Stevens, Fernandez and Martin | F32: 19 | G32: 57 | H32: 57
A33: PROD31 | B33: Basketball | C33: Sports | D33: Team Sports | E33: Nolan-Snow | F33: 204 | G33: 281 | H33: 281
A34: PROD32 | B34: Vitamin C Face Serum | C34: Beauty | D34: Skincare | E34: Griffin Ltd | F34: 283 | G34: 244 | H34: 244
A35: PROD33 | B35: Modern Wall Clock | C35: Home | D35: Decor | E35: Weiss-Watson | F35: 179 | G35: 305 | H35: 305
A36: PROD34 | B36: Gaming Mechanical Keyboard | C36: Electronics | D36: Computer | E36: Lucero LLC | F36: 419 | G36: 86 | H36: 86
A37: PROD35 | B37: Bedroom Table Lamp | C37: Home | D37: Lighting | E37: Jones LLC | F37: 382 | G37: 329 | H37: 329
A38: PROD36 | B38: Women's Summer Dress | C38: Clothing | D38: Tops | E38: Smith-Mills | F38: 223 | G38: 154 | H38: 154
A39: PROD37 | B39: Men's Casual Sneakers | C39: Clothing | D39: Footwear | E39: Hogan-Lee | F39: 353 | G39: 214 | H39: 214
A40: PROD38 | B40: Sports Water Hydration Pack | C40: Sports | D40: Outdoor | E40: Sims-Smith | F40: 135 | G40: 394 | H40: 394
...

Sheet Store_Raw
A1: Store_ID | B1: Store_Name | C1: Region | D1: City | E1: Store_Type
A2: STORE0 | B2: Rivera-Warner | C2: East | D2: Washingtonfurt | E2: Flagship
A3: STORE1 | B3: Martinez, Adkins and Johnson | C3: North | D3: Danielmouth | E3: Flagship
A4: STORE2 | B4: Black-Horn | C4: South | D4: North Nancyview | E4: Outlet
A5: STORE3 | B5: Johnson-Wright | C5: North | D5: Hoodberg | E5: Outlet
A6: STORE4 | B6: Alexander Group | C6: South | D6: Port Sharon | E6: Online
A7: STORE5 | B7: Gray Ltd | C7: North | D7: New Michaelchester | E7: Outlet
A8: STORE6 | B8: Benson-Elliott | C8: East | D8: Port Josephberg | E8: Online
A9: STORE7 | B9: Martinez-Mullins | C9: South | D9: Williamsfurt | E9: Online
A10: STORE8 | B10: Bean, Jones and Park | C10: West | D10: Thompsonborough | E10: Online
A11: STORE9 | B11: Moore, Padilla and Butler | C11: South | D11: East Johnstad | E11: Flagship
A12: STORE10 | B12: Hill, Wagner and Ballard | C12: East | D12: East Davidville | E12: Online
... A21: STORE19 | B21: Mann-Austin | C21: East | D21: Vasquezborough | E21: Online

Sheet Sales_Fact Raw
A1: Sales_ID | B1: Order_Date | C1: Customer_ID | D1: Product_ID | E1: Store_ID | F1: Quantity | G1: Unit_Price | H1: Discount | I1: Payment_Type | J1: Total_Amount
A2: SALE66 | B2: 45213 | C2: CUST1269 | D2: PROD77 | E2: STORE2 | F2: 4 | G2: 814.25 | H2: 0.18 | I2: Credit Card | J2: 2670.74
A3: SALE799 | B3: 45213 | C3: CUST1235 | D3: PROD92 | E3: STORE11 | F3: 4 | G3: 23.57 | H3: 0.1 | I3: Credit Card | J3: 84.852
A4: SALE1173 | B4: 45213 | C4: CUST1283 | D4: PROD56 | E4: STORE16 | F4: 2 | G4: 805.08 | H4: 0.27 | I4: PayPal | J4: 1175.4168
A5: SALE105 | B5: 45214 | C5: CUST1002 | D5: PROD79 | E5: STORE17 | F5: 2 | G5: 418.23 | H5: 0.28 | I5: Credit Card | J5: 602.2512
A6: SALE1727 | B6: 45214 | C6: CUST1023 | D6: PROD12 | E6: STORE0 | F6: 1 | G6: 145.48 | H6: 0.1 | I6: COD | J6: 130.932
A7: SALE34 | B7: 45215 | C7: CUST1344 | D7: PROD79 | E7: STORE1 | F7: =TEXT(F7,0) -> 0 | G7: 873.22 | H7: 0.18 | I7: Credit Card | J7: 2148.1212
A8: SALE1071 | B8: 45215 | C8: CUST1225 | D8: PROD89 | E8: STORE2 | F8: 4 | G8: 753.83 | H8: 0.24 | I8: Credit Card | J8: 2291.6432
A9: SALE1221 | B9: 45216 | C9: CUST1010 | D9: PROD52 | E9: STORE19 | F9: 2 | G9: 441.03 | H9: 0.23 | I9: COD | J9: 679.1862
A10: SALE1958 | B10: 45216 | C10: CUST1072 | D10: PROD64 | E10: STORE19 | F10: 3 | G10: 449.99 | H10: 0.17 | I10: COD | J10: 1120.4751
A11: SALE30 | B11: 45217 | C11: CUST1028 | D11: PROD5 | E11: STORE19 | F11: 1 | G11: 429.38 | H11: 0.13 | I11: PayPal | J11: 373.5606
A12: SALE369 | B12: 45217 | C12: CUST1448 | D12: PROD65 | E12: STORE3 | F12: 4 | G12: 269.49 | H12: 0.07 | I12: PayPal | J12: 1002.5028
A13: SALE732 | B13: 45217 | C13: CUST1224 | D13: PROD50 | E13: STORE17 | F13: 1 | G13: 498.61 | H13: 0.04 | I13: PayPal | J13: 478.6656
A14: SALE1007 | B14: 45217 | C14: CUST1198 | D14: PROD75 | E14: STORE2 | F14: 2 | G14: 541.52 | H14: 0.26 | I14: PayPal | J14: 801.4496
A15: SALE1274 | B15: 45217 | C15: CUST1198 | D15: PROD60 | E15: STORE11 | F15: 3 | G15: 257.11 | H15: 0.26 | I15: COD | J15: 570.7842
A16: SALE48 | B16: 45218 | C16: CUST1203 | D16: PROD44 | E16: STORE17 | F16: 1 | G16: 517.13 | H16: 0.28 | I16: Credit Card | J16: 372.3336
A17: SALE340 | B17: 45218 | C17: CUST1047 | D17: PROD17 | E17: STORE19 | F17: 3 | G17: 997.95 | H17: 0.09 | I17: COD | J17: 2724.4035
A18: SALE217 | B18: 45219 | C18: CUST1266 | D18: PROD15 | E18: STORE19 | F18: 1 | G18: 332.82 | H18: 0.14 | I18: PayPal | J18: 286.2252
A19: SALE1116 | B19: 45219 | C19: CUST1140 | D19: PROD13 | E19: STORE8 | F19: 3 | G19: 278.38 | H19: 0.03 | I19: Credit Card | J19: 810.0858
... A153: SALE79 | B153: 45268 | C153: CUST1115 | D153: PROD21 | E153: STORE2 | F153: 1 | G153: 341.17 | H153: 0.15 | I153: Credit Card | J153: 289.9945
A154: SALE84 | B154: 45268 | C154: CUST1423 | D154: PROD46 | E154: STORE17 | F154: 1 | G154: 773.57 | H154: 0.05 | I154: COD | J154: =F154*G154*(1-H154) -> 734.8915
A155: SALE300 | B155: 45268 | C155: CUST1198 | D155: PROD12 | E155: STORE15 | F155: 4 | G155: 889.47 | H155: 0.24 | I155: Credit Card | J155: 2703.9888
A156: SALE1328 | B156: 45268 | C156: CUST1334 | D156: PROD5 | E156: STORE8 | F156: 3 | G156: 120.77 | H156: 0.29 | I156: PayPal | J156: 257.2401
A157: SALE1581 | B157: 45268 | C157: CUST1307 | D157: PROD46 | E157: STORE10 | F157: 1 | G157: 209.7 | H157: 0.2 | I157: PayPal | J157: 167.76
A158: SALE1681 | B158: 45268 | C158: CUST1136 | D158: PROD37 | E158: STORE15 | F158: 3 | G158: 281.96 | H158: 0.01 | I158: COD | J158: 837.4212
A159: SALE1702 | B159: 45268 | C159: CUST1217 | D159: PROD37 | E159: STORE7 | F159: 2 | G159: 985.79 | H159: 0.04 | I159: PayPal | J159: 1892.7168
A160: SALE166 | B160: 45269 | C160: CUST1295 | D160: PROD69 | E160: STORE8 | F160: 4 | G160: 714.47 | H160: 0.18 | I160: COD | J160: 2343.4616
A161: SALE1892 | B161: 45269 | C161: CUST1059 | D161: PROD70 | E161: STORE14 | F161: 2 | G161: 47.3 | H161: 0.01 | I161: PayPal | J161: 93.654
A162: SALE68 | B162: 45270 | C162: CUST1372 | D162: PROD72 | E162: STORE10 | F162: 4 | G162: 62.48 | H162: 0.18 | I162: Credit Card | J162: 204.9344
A163: SALE461 | B163: 45270 | C163: CUST1129 | D163: PROD91 | E163: STORE11 | F163: 4 | G163: 202.46 | H163: 0.24 | I163: Credit Card | J163: 615.4784
A164: SALE685 | B164: 45270 | C164: CUST1456 | D164: PROD88 | E164: STORE13 | F164: 4 | G164: 451.41 | H164: 0.06 | I164: PayPal | J164: 1697.3016
A165: SALE1119 | B165: 45271 | C165: CUST1455 | D165: PROD21 | E165: STORE4 | F165: 2 | G165: 961.84 | H165: 0.25 | I165: PayPal | J165: 1442.76
A166: SALE980 | B166: 45272 | C166: CUST1232 | D166: PROD66 | E166: STORE8 | F166: 4 | G166: 649.52 | H166: 0.11 | I166: Credit Card | J166: 2312.2912
... A224: SALE1948 | B224: 45293 | C224: CUST1425 | D224: PROD94 | E224: STORE10 | F224: 4 | G224: 101.25 | H224: 0.16 | I224: PayPal | J224: 340.2
A225: SALE26 | B225: 45294 | C225: CUST1213 | D225: PROD98 | E225: STORE8 | F225: 4 | G225: 156.16 | H225: =TEXT(H225,0) -> 0 | I225: Credit Card | J225: 599.6544
A226: SALE896 | B226: 45294 | C226: CUST1431 | D226: PROD96 | E226: STORE16 | F226: 1 | G226: 835.17 | H226: 0.02 | I226: COD | J226: 818.4666
A227: SALE1645 | B227: 45294 | C227: CUST1343 | D227: PROD39 | E227: STORE5 | F227: 1 | G227: 702.27 | H227: 0.17 | I227: COD | J227: 582.8841
A228: SALE548 | B228: 45295 | C228: CUST1123 | D228: PROD12 | E228: STORE15 | F228: 2 | G228: 562.97 | H228: 0.2 | I228: Credit Card | J228: 900.752
A229: SALE1409 | B229: 45296 | C229: CUST1067 | D229: PROD25 | E229: STORE15 | F229: 2 | G229: 795.37 | H229: 0.2 | I229: COD | J229: 1272.592
A230: SALE1525 | B230: 45296 | C230: CUST1296 | D230: PROD23 | E230: STORE18 | F230: 1 | G230: 616.82 | H230: 0.24 | I230: Credit Card | J230: 468.7832
...

Sheet Customer_Cleaned
A1: Customer_ID | B1: Name | C1: Age | D1: Gender | E1: City | F1: State | G1: Country | H1: Loyalty_Level
A2: CUST1000 | B2: Sheena Bonilla | C2: 55 | D2: Male | E2: Donaldton | F2: North Carolina | G2: USA | H2: =IF(C2>=50,"Platinum",IF(C2>=35,"Silver","Bronze")) -> Platinum
A3: CUST1001 | B3: Eugene Nelson | C3: 26 | D3: Female | E3: Phillipsmouth | F3: North Dakota | G3: USA | H3: =IF(C3>=50,"Platinum",IF(C3>=35,"Silver","Bronze")) -> Bronze
A4: CUST1002 | B4: Dr. Benjamin Price | C4: 29 | D4: Female | E4: Kylebury | F4: Alabama | G4: USA | H4: =IF(C4>=50,"Platinum",IF(C4>=35,"Silver","Bronze")) -> Bronze
A5: CUST1003 | B5: Jeremy Harris | C5: 59 | D5: Female | E5: Thomastown | F5: Ohio | G5: USA | H5: =IF(C5>=50,"Platinum",IF(C5>=35,"Silver","Bronze")) -> Platinum
A6: CUST1004 | B6: Caroline Collins | C6: 64 | D6: Female | E6: Nicholasshire | F6: California | G6: USA | H6: =IF(C6>=50,"Platinum",IF(C6>=35,"Silver","Bronze")) -> Platinum
A7: CUST1005 | B7: Christine Vaughn | C7: 24 | D7: Male | E7: East Amandamouth | F7: Oregon | G7: USA | H7: =IF(C7>=50,"Platinum",IF(C7>=35,"Silver","Bronze")) -> Bronze
A8: CUST1006 | B8: Amber Jackson | C8: 29 | D8: Female | E8: Deborahborough | F8: South Dakota | G8: USA | H8: =IF(C8>=50,"Platinum",IF(C8>=35,"Silver","Bronze")) -> Bronze
A9: CUST1007 | B9: Daniel Boyd | C9: 29 | D9: Female | E9: West Pamelafurt | F9: West Virginia | G9: USA | H9: =IF(C9>=50,"Platinum",IF(C9>=35,"Silver","Bronze")) -> Bronze
A10: CUST1008 | B10: Melissa Howard | C10: 53 | D10: Female | E10: Maynardton | F10: New Hampshire | G10: USA | H10: =IF(C10>=50,"Platinum",IF(C10>=35,"Silver","Bronze")) -> Platinum
A11: CUST1009 | B11: Ms. Maria Leach | C11: 64 | D11: Male | E11: Melissashire | F11: Pennsylvania | G11: USA | H11: =IF(C11>=50,"Platinum",IF(C11>=35,"Silver","Bronze")) -> Platinum
A12: CUST1010 | B12: Dominic Page | C12: 53 | D12: Male | E12: Port Michaelburgh | F12: Pennsylvania | G12: USA | H12: =IF(C12>=50,"Platinum",IF(C12>=35,"Silver","Bronze")) -> Platinum
A13: CUST1011 | B13: Brian Lopez | C13: 28 | D13: Female | E13: East Krista | F13: New York | G13: USA | H13: =IF(C13>=50,"Platinum",IF(C13>=35,"Silver","Bronze")) -> Bronze
... A501: CUST1499 | B501: Philip Pennington | C501: 27 | D501: Female | E501: East Valerieview | F501: Oregon | G501: USA | H501: =IF(C501>=50,"Platinum",IF(C501>=35,"Silver","Bronze")) -> Bronze

Sheet Product_Cleaned
A1: Product_ID | B1: Product_Name | C1: Category | D1: Sub_Category | E1: Brand | F1: Cost | G1: Stock
A2: PROD0 | B2: Brother Laser Printer | C2: Electronics | D2: Computer | E2: Hunt Inc | F2: 112 | G2: 416
A3: PROD26 | B3: Wireless Bluetooth Speaker | C3: Electronics | D3: Audio | E3: Reed-Schmidt | F3: 322 | G3: 213
A4: PROD34 | B4: Gaming Mechanical Keyboard | C4: Electronics | D4: Computer | E4: Lucero LLC | F4: 419 | G4: 86
A5: PROD39 | B5: Portable Power Bank | C5: Electronics | D5: Mobile | E5: Cummings and Sons | F5: 326 | G5: 301
A6: PROD40 | B6: Noise-Canceling Headphones | C6: Electronics | D6: Audio | E6: Taylor-Hart | F6: 38 | G6: 378
A7: PROD42 | B7: Smart Home WiFi Camera | C7: Electronics | D7: Accessories | E7: Holmes LLC | F7: 450 | G7: 389
A8: PROD43 | B8: USB External Hard Drive | C8: Electronics | D8: Computer | E8: Robinson Inc | F8: 253 | G8: 266
A9: PROD48 | B9: Car Dashboard Phone Holder | C9: Electronics | D9: Accessories | E9: Byrd, Stewart and Valdez | F9: 177 | G9: 103
A10: PROD51 | B10: HDMI Cable – 2m | C10: Electronics | D10: Accessories | E10: Bautista, Green and Hale | F10: 88 | G10: 246
A11: PROD62 | B11: Laptop Cooling Pad | C11: Electronics | D11: Computer | E11: Murray, Gould and Ware | F11: 86 | G11: 222
A12: PROD67 | B12: Smart LED Light Strip | C12: Electronics | D12: Accessories | E12: Flores-Davis | F12: 349 | G12: 476
A13: PROD74 | B13: Bluetooth Car Audio System | C13: Electronics | D13: Audio | E13: Bruce-Bowen | F13: 403 | G13: 159
... A18: PROD98 | B18: Portable Bluetooth Speaker | C18: Electronics | D18: Audio | E18: Flores-King | F18: 431 | G18: 73
A19: PROD1 | B19: Men's Graphic T-Shirt | C19: Clothing | D19: Tops | E19: Terry-Moore | F19: 342 | G19: 181
A20: PROD2 | B20: Women's Casual Hoodie | C20: Clothing | D20: Outerwear | E20: Sims Inc | F20: 254 | G20: 352
A21: PROD3 | B21: Men's Running Jacket | C21: Clothing | D21: Outerwear | E21: Pineda Ltd | F21: 364 | G21: 452
A22: PROD4 | B22: Women's Yoga Pants | C22: Clothing | D22: Bottoms | E22: Gonzales-Davis | F22: 306 | G22: 487
A23: PROD5 | B23: Men's Leather Belt | C23: Clothing | D23: Accessories | E23: Baldwin, Garza and Gonzalez | F23: 261 | G23: 59
A24: PROD6 | B24: Herbal Face Moisturizer | C24: Beauty | D24: Skincare | E24: Davidson PLC | F24: 312 | G24: 343
A25: PROD7 | B25: LED Table Lamp | C25: Home | D25: Lighting | E25: Harrell LLC | F25: 218 | G25: 360
A26: PROD8 | B26: Wireless Bluetooth Earbuds | C26: Electronics | D26: Audio | E26: Perez-Johnston | F26: 439 | G26: 268
A27: PROD9 | B27: Adjustable Dumbbell Set | C27: Sports | D27: Fitness | E27: Hill PLC | F27: 495 | G27: 154
A28: PROD10 | B28: Ceramic Kitchen Bowl Set | C28: Home | D28: Kitchen | E28: Hamilton Group | F28: 298 | G28: 214
A29: PROD11 | B29: HD Smart TV Stick | C29: Electronics | D29: Accessories | E29: Gibson, Hobbs and Weaver | F29: 449 | G29: 296
A30: PROD12 | B30: Hair Strengthening Shampoo | C30: Beauty | D30: Haircare | E30: Rice LLC | F30: 115 | G30: 125
A31: PROD13 | B31: USB-C Fast Charger | C31: Electronics | D31: Accessories | E31: Dawson-Perkins | F31: 242 | G31: 485
A32: PROD14 | B32: Decorative Wall Mirror | C32: Home | D32: Decor | E32: Luna, Anderson and Bowman | F32: 48 | G32: 224
A33: PROD15 | B33: 4K Home Projector | C33: Electronics | D33: Appliances | E33: Thomas LLC | F33: 465 | G33: 82
A34: PROD16 | B34: Beard Grooming Kit | C34: Beauty | D34: Grooming | E34: Erickson-Green | F34: 337 | G34: 210
A35: PROD17 | B35: Soccer Training Cone Set | C35: Sports | D35: Accessories | E35: Ford, Murphy and Wilson | F35: 144 | G35: 496
A36: PROD18 | B36: Women's Denim Jeans | C36: Clothing | D36: Bottoms | E36: Guerra-Hendrix | F36: 254 | G36: 343
A37: PROD19 | B37: Knee Support Brace | C37: Sports | D37: Equipment | E37: May-Reese | F37: 21 | G37: 65
A38: PROD20 | B38: Outdoor Sports Water Bottle | C38: Sports | D38: Accessories | E38: Soto-Ellis | F38: 131 | G38: 268
A39: PROD21 | B39: Multi-Purpose Storage Box | C39: Home | D39: Storage | E39: Gardner-Montes | F39: 123 | G39: 76
A40: PROD22 | B40: Carbon Fiber Tennis Racket | C40: Sports | D40: Equipment | E40: Flores, Pineda and Rodriguez | F40: 484 | G40: 432
A41: PROD23 | B41: Men's Formal Shirt | C41: Clothing | D41: Tops | E41: Moon, Mora and Santos | F41: 254 | G41: 360
A42: PROD24 | B42: Foldable Camping Chair | C42: Sports | D42: Outdoor | E42: Cook Ltd | F42: 166 | G42: 340
A43: PROD25 | B43: Women's Scarf Set | C43: Clothing | D43: Accessories | E43: Brown and Sons | F43: 174 | G43: 268
A44: PROD27 | B44: Decorative Floor Vase | C44: Home | D44: Decor | E44: Khan, Jones and Paul | F44: 254 | G44: 378
...

Sheet Sales_Fact cleaned
A1: Order_Date | B1: Customer_ID | C1: Product_ID | D1: Product_Name | E1: Category | F1: Sub_Category | G1: Brand | H1: Store_ID | I1: Store_Name | J1: Region | K1: City | L1: Store_Type | M1: Name | N1: Age | O1: Gender | P1: Loyalty_Level | Q1: State | R1: Country | S1: Quantity | T1: Unit_Price | U1: Discount | V1: Total_Amount | W1: Payment_Type
A2: 45213 | B2: CUST1181 | C2: PROD81 | D2: =VLOOKUP(C2,Product_Cleaned!$A$2:$B$101,2,FALSE) -> Badminton Racket Set | E2: =VLOOKUP(C2,Product_Cleaned!$A$2:$C$101,3,FALSE) -> Sports | F2: =VLOOKUP(C2,Product_Cleaned!$A$2:$E$101,4,FALSE) -> Equipment | G2: =VLOOKUP('Sales_Fact cleaned'!C698,Product_Cleaned!$A$2:$E$101,5, FALSE) -> Green, Powell and Palmer | H2: STORE7 | I2: =_xlfn.XLOOKUP(H2,Store_Raw!$A$2:$A$21,Store_Raw!$B$2:$B$21) -> Martinez-Mullins | J2: =_xlfn.XLOOKUP(H2,Store_Raw!$A$2:$A$21,Store_Raw!$C$2:$C$21) -> South | K2: =_xlfn.XLOOKUP(H2,Store_Raw!$A$2:$A$21,Store_Raw!$D$2:$D$21) -> Williamsfurt | L2: =_xlfn.XLOOKUP(H2,Store_Raw!$A$2:$A$21,Store_Raw!$E$2:$E$21) -> Online | M2: =VLOOKUP(B2,Customer_Cleaned!$A$2:$H$501,2,FALSE) -> Erin Ward | N2: =VLOOKUP(B2,Customer_Cleaned!$A$2:$H$501,3,FALSE) -> 60 | O2: =VLOOKUP(B2,Customer_Cleaned!$A$2:$H$501,4,FALSE) -> Male | P2: =VLOOKUP(B2,Customer_Cleaned!$A$2:$H$501,8,FALSE) -> Platinum | Q2: =_xlfn.XLOOKUP('Sales_Fact cleaned'!B698,Customer_Cleaned!$A$2:$A$501,Customer_Cleaned!$F$2:$F$501) -> Missouri | R2: =_xlfn.XLOOKUP(B2,Customer_Cleaned!$A$2:$A$501,Customer_Cleaned!$G$2:$G$501) -> USA | S2: 1 | T2: 26.37 | U2: 0.3 | V2: 18.459 | W2: Credit Card
A3: 45213 | B3: CUST1089 | C3: PROD20 | D3: =VLOOKUP(C3,Product_Cleaned!$A$2:$B$101,2,FALSE) -> Outdoor Sports Water Bottle | E3: =VLOOKUP(C3,Product_Cleaned!$A$2:$C$101,3,FALSE) -> Sports | F3: =VLOOKUP(C3,Product_Cleaned!$A$2:$E$101,4,FALSE) -> Accessories | G3: =VLOOKUP('Sales_Fact cleaned'!C1502,Product_Cleaned!$A$2:$E$101,5, FALSE) -> Harris Inc | H3: STORE18 | I3: =_xlfn.XLOOKUP(H3,Store_Raw!$A$2:$A$21,Store_Raw!$B$2:$B$21) -> Guerrero-Schmitt | J3: =_xlfn.XLOOKUP(H3,Store_Raw!$A$2:$A$21,Store_Raw!$C$2:$C$21) -> East | K3: =_xlfn.XLOOKUP(H3,Store_Raw!$A$2:$A$21,Store_Raw!$D$2:$D$21) -> East Stevechester | L3: =_xlfn.XLOOKUP(H3,Store_Raw!$A$2:$A$21,Store_Raw!$E$2:$E$21) -> Flagship | M3: =VLOOKUP(B3,Customer_Cleaned!$A$2:$H$501,2,FALSE) -> Jamie Yoder | N3: =VLOOKUP(B3,Customer_Cleaned!$A$2:$H$501,3,FALSE) -> 43 | O3: =VLOOKUP(B3,Customer_Cleaned!$A$2:$H$501,4,FALSE) -> Male | P3: =VLOOKUP(B3,Customer_Cleaned!$A$2:$H$501,8,FALSE) -> Silver | Q3: =_xlfn.XLOOKUP('Sales_Fact cleaned'!B1502,Customer_Cleaned!$A$2:$A$501,Customer_Cleaned!$F$2:$F$501) -> Pennsylvania | R3: =_xlfn.XLOOKUP(B3,Customer_Cleaned!$A$2:$A$501,Customer_Cleaned!$G$2:$G$501) -> USA | S3: 1 | T3: 27.83 | U3: 0.3 | V3: 19.481 | W3: Credit Card
A4: 45213 | B4: CUST1343 | C4: PROD38 | D4: =VLOOKUP(C4,Product_Cleaned!$A$2:$B$101,2,FALSE) -> Sports Water Hydration Pack | E4: =VLOOKUP(C4,Product_Cleaned!$A$2:$C$101,3,FALSE) -> Sports | F4: =VLOOKUP(C4,Product_Cleaned!$A$2:$E$101,4,FALSE) -> Outdoor | G4: =VLOOKUP('Sales_Fact cleaned'!C1500,Product_Cleaned!$A$2:$E$101,5, FALSE) -> Larson Ltd | H4: STORE12 | I4: =_xlfn.XLOOKUP(H4,Store_Raw!$A$2:$A$21,Store_Raw!$B$2:$B$21) -> Thomas, Bridges and Harris | J4: =_xlfn.XLOOKUP(H4,Store_Raw!$A$2:$A$21,Store_Raw!$C$2:$C$21) -> North | K4: =_xlfn.XLOOKUP(H4,Store_Raw!$A$2:$A$21,Store_Raw!$D$2:$D$21) -> Sabrinatown | L4: =_xlfn.XLOOKUP(H4,Store_Raw!$A$2:$A$21,Store_Raw!$E$2:$E$21) -> Online | M4: =VLOOKUP(B4,Customer_Cleaned!$A$2:$H$501,2,FALSE) -> Ryan Moore | N4: =VLOOKUP(B4,Customer_Cleaned!$A$2:$H$501,3,FALSE) -> 38 | O4: =VLOOKUP(B4,Customer_Cleaned!$A$2:$H$501,4,FALSE) -> Male | P4: =VLOOKUP(B4,Customer_Cleaned!$A$2:$H$501,8,FALSE) -> Silver | Q4: =_xlfn.XLOOKUP('Sales_Fact cleaned'!B1500,Customer_Cleaned!$A$2:$A$501,Customer_Cleaned!$F$2:$F$501) -> North Dakota | R4: =_xlfn.XLOOKUP(B4,Customer_Cleaned!$A$2:$A$501,Customer_Cleaned!$G$2:$G$501) -> USA | S4: 1 | T4: 21.14 | U4: 0.06 | V4: 19.8716 | W4: PayPal
A5: 45214 | B5: CUST1293 | C5: PROD73 | D5: =VLOOKUP(C5,Product_Cleaned!$A$2:$B$101,2,FALSE) -> Shin Guards – Adult | E5: =VLOOKUP(C5,Product_Cleaned!$A$2:$C$101,3,FALSE) -> Sports | F5: =VLOOKUP(C5,Product_Cleaned!$A$2:$E$101,4,FALSE) -> Team Sports | G5: =VLOOKUP('Sales_Fact cleaned'!C943,Product_Cleaned!$A$2:$E$101,5, FALSE) -> Montgomery, Benton and Miller | H5: STORE3 | I5: =_xlfn.XLOOKUP(H5,Store_Raw!$A$2:$A$21,Store_Raw!$B$2:$B$21) -> Johnson-Wright | J5: =_xlfn.XLOOKUP(H5,Store_Raw!$A$2:$A$21,Store_Raw!$C$2:$C$21) -> North | K5: =_xlfn.XLOOKUP(H5,Store_Raw!$A$2:$A$21,Store_Raw!$D$2:$D$21) -> Hoodberg | L5: =_xlfn.XLOOKUP(H5,Store_Raw!$A$2:$A$21,Store_Raw!$E$2:$E$21) -> Outlet | M5: =VLOOKUP(B5,Customer_Cleaned!$A$2:$H$501,2,FALSE) -> Gloria Taylor | N5: =VLOOKUP(B5,Customer_Cleaned!$A$2:$H$501,3,FALSE) -> 56 | O5: =VLOOKUP(B5,Customer_Cleaned!$A$2:$H$501,4,FALSE) -> Female | P5: =VLOOKUP(B5,Customer_Cleaned!$A$2:$H$501,8,FALSE) -> Platinum | Q5: =_xlfn.XLOOKUP('Sales_Fact cleaned'!B943,Customer_Cleaned!$A$2:$A$501,Customer_Cleaned!$F$2:$F$501) -> Kansas | R5: =_xlfn.XLOOKUP(B5,Customer_Cleaned!$A$2:$A$501,Customer_Cleaned!$G$2:$G$501) -> USA | S5: 1 | T5: 24.13 | U5: 0 | V5: 24.13 | W5: Credit Card
A6: 45214 | B6: CUST1384 | C6: PROD74 | D6: =VLOOKUP(C6,Product_Cleaned!$A$2:$B$101,2,FALSE) -> Bluetooth Car Audio System | E6: =VLOOKUP(C6,Product_Cleaned!$A$2:$C$101,3,FALSE) -> Electronics | F6: =VLOOKUP(C6,Product_Cleaned!$A$2:$E$101,4,FALSE) -> Audio | G6: =VLOOKUP('Sales_Fact cleaned'!C1792,Product_Cleaned!$A$2:$E$101,5, FALSE) -> Anderson-Riley | H6: STORE10 | I6: =_xlfn.XLOOKUP(H6,Store_Raw!$A$2:$A$21,Store_Raw!$B$2:$B$21) -> Hill, Wagner and Ballard | J6: =_xlfn.XLOOKUP(H6,Store_Raw!$A$2:$A$21,Store_Raw!$C$2:$C$21) -> East | K6: =_xlfn.XLOOKUP(H6,Store_Raw!$A$2:$A$21,Store_Raw!$D$2:$D$21) -> East Davidville | L6: =_xlfn.XLOOKUP(H6,Store_Raw!$A$2:$A$21,Store_Raw!$E$2:$E$21) -> Online | M6: =VLOOKUP(B6,Customer_Cleaned!$A$2:$H$501,2,FALSE) -> Andrew Mason | N6: =VLOOKUP(B6,Customer_Cleaned!$A$2:$H$501,3,FALSE) -> 52 | O6: =VLOOKUP(B6,Customer_Cleaned!$A$2:$H$501,4,FALSE) -> Female | P6: =VLOOKUP(B6,Customer_Cleaned!$A$2:$H$501,8,FALSE) -> Platinum | Q6: =_xlfn.XLOOKUP('Sales_Fact cleaned'!B1792,Customer_Cleaned!$A$2:$A$501,Customer_Cleaned!$F$2:$F$501) -> Nebraska | R6: =_xlfn.XLOOKUP(B6,Customer_Cleaned!$A$2:$A$501,Customer_Cleaned!$G$2:$G$501) -> USA | S6: 1 | T6: 30.94 | U6: 0.21 | V6: 24.4426 | W6: COD
A7: 45215 | B7: CUST1241 | C7: PROD15 | D7: =VLOOKUP(C7,Product_Cleaned!$A$2:$B$101,2,FALSE) -> 4K Home Projector | E7: =VLOOKUP(C7,Product_Cleaned!$A$2:$C$101,3,FALSE) -> Electronics | F7: =VLOOKUP(C7,Product_Cleaned!$A$2:$E$101,4,FALSE) -> Appliances | G7: =VLOOKUP('Sales_Fact cleaned'!C463,Product_Cleaned!$A$2:$E$101,5, FALSE) -> Hernandez Inc | H7: STORE14 | I7: =_xlfn.XLOOKUP(H7,Store_Raw!$A$2:$A$21,Store_Raw!$B$2:$B$21) -> Mcdonald Inc | J7: =_xlfn.XLOOKUP(H7,Store_Raw!$A$2:$A$21,Store_Raw!$C$2:$C$21) -> South | K7: =_xlfn.XLOOKUP(H7,Store_Raw!$A$2:$A$21,Store_Raw!$D$2:$D$21) -> Christopherland | L7: =_xlfn.XLOOKUP(H7,Store_Raw!$A$2:$A$21,Store_Raw!$E$2:$E$21) -> Outlet | M7: =VLOOKUP(B7,Customer_Cleaned!$A$2:$H$501,2,FALSE) -> Mr. William Horton | N7: =VLOOKUP(B7,Customer_Cleaned!$A$2:$H$501,3,FALSE) -> 31 | O7: =VLOOKUP(B7,Customer_Cleaned!$A$2:$H$501,4,FALSE) -> Male | P7: =VLOOKUP(B7,Customer_Cleaned!$A$2:$H$501,8,FALSE) -> Bronze | Q7: =_xlfn.XLOOKUP('Sales_Fact cleaned'!B463,Customer_Cleaned!$A$2:$A$501,Customer_Cleaned!$F$2:$F$501) -> New Mexico | R7: =_xlfn.XLOOKUP(B7,Customer_Cleaned!$A$2:$A$501,Customer_Cleaned!$G$2:$G$501) -> USA | S7: 1 | T7: 31.36 | U7: 0.21 | V7: 24.7744 | W7: Credit Card
A8: 45215 | B8: CUST1105 | C8: PROD57 | D8: =VLOOKUP(C8,Product_Cleaned!$A$2:$B$101,2,FALSE) -> Foam Roller | E8: =VLOOKUP(C8,Product_Cleaned!$A$2:$C$101,3,FALSE) -> Sports | F8: =VLOOKUP(C8,Product_Cleaned!$A$2:$E$101,4,FALSE) -> Fitness | G8: =VLOOKUP('Sales_Fact cleaned'!C1317,Product_Cleaned!$A$2:$E$101,5, FALSE) -> Robinson-Brown | H8: STORE3 | I8: =_xlfn.XLOOKUP(H8,Store_Raw!$A$2:$A$21,Store_Raw!$B$2:$B$21) -> Johnson-Wright | J8: =_xlfn.XLOOKUP(H8,Store_Raw!$A$2:$A$21,Store_Raw!$C$2:$C$21) -> North | K8: =_xlfn.XLOOKUP(H8,Store_Raw!$A$2:$A$21,Store_Raw!$D$2:$D$21) -> Hoodberg | L8: =_xlfn.XLOOKUP(H8,Store_Raw!$A$2:$A$21,Store_Raw!$E$2:$E$21) -> Outlet | M8: =VLOOKUP(B8,Customer_Cleaned!$A$2:$H$501,2,FALSE) -> Lance Baker | N8: =VLOOKUP(B8,Customer_Cleaned!$A$2:$H$501,3,FALSE) -> 50 | O8: =VLOOKUP(B8,Customer_Cleaned!$A$2:$H$501,4,FALSE) -> Female | P8: =VLOOKUP(B8,Customer_Cleaned!$A$2:$H$501,8,FALSE) -> Platinum | Q8: =_xlfn.XLOOKUP('Sales_Fact cleaned'!B1317,Customer_Cleaned!$A$2:$A$501,Customer_Cleaned!$F$2:$F$501) -> New Hampshire | R8: =_xlfn.XLOOKUP(B8,Customer_Cleaned!$A$2:$A$501,Customer_Cleaned!$G$2:$G$501) -> USA | S8: 1 | T8: 38.95 | U8: 0.28 | V8: 28.044 | W8: Credit Card
A9: 45216 | B9: CUST1104 | C9: PROD31 | D9: =VLOOKUP(C9,Product_Cleaned!$A$2:$B$101,2,FALSE) -> Basketball | E9: =VLOOKUP(C9,Product_Cleaned!$A$2:$C$101,3,FALSE) -> Sports | F9: =VLOOKUP(C9,Product_Cleaned!$A$2:$E$101,4,FALSE) -> Team Sports | G9: =VLOOKUP('Sales_Fact cleaned'!C1421,Product_Cleaned!$A$2:$E$101,5, FALSE) -> Allison Ltd | H9: STORE3 | I9: =_xlfn.XLOOKUP(H9,Store_Raw!$A$2:$A$21,Store_Raw!$B$2:$B$21) -> Johnson-Wright | J9: =_xlfn.XLOOKUP(H9,Store_Raw!$A$2:$A$21,Store_Raw!$C$2:$C$21) -> North | K9: =_xlfn.XLOOKUP(H9,Store_Raw!$A$2:$A$21,Store_Raw!$D$2:$D$21) -> Hoodberg | L9: =_xlfn.XLOOKUP(H9,Store_Raw!$A$2:$A$21,Store_Raw!$E$2:$E$21) -> Outlet | M9: =VLOOKUP(B9,Customer_Cleaned!$A$2:$H$501,2,FALSE) -> Christopher Lester | N9: =VLOOKUP(B9,Customer_Cleaned!$A$2:$H$501,3,FALSE) -> 64 | O9: =VLOOKUP(B9,Customer_Cleaned!$A$2:$H$501,4,FALSE) -> Male | P9: =VLOOKUP(B9,Customer_Cleaned!$A$2:$H$501,8,FALSE) -> Platinum | Q9: =_xlfn.XLOOKUP('Sales_Fact cleaned'!B1421,Customer_Cleaned!$A$2:$A$501,Customer_Cleaned!$F$2:$F$501) -> Pennsylvania | R9: =_xlfn.XLOOKUP(B9,Customer_Cleaned!$A$2:$A$501,Customer_Cleaned!$G$2:$G$501) -> USA | S9: 1 | T9: 36.8 | U9: 0.18 | V9: 30.176 | W9: COD
A10: 45216 | B10: CUST1377 | C10: PROD78 | D10: =VLOOKUP(C10,Product_Cleaned!$A$2:$B$101,2,FALSE) -> Essential Oil Diffuser | E10: =VLOOKUP(C10,Product_Cleaned!$A$2:$C$101,3,FALSE) -> Home | F10: =VLOOKUP(C10,Product_Cleaned!$A$2:$E$101,4,FALSE) -> Decor | G10: =VLOOKUP('Sales_Fact cleaned'!C387,Product_Cleaned!$A$2:$E$101,5, FALSE) -> Moon, Mora and Santos | H10: STORE4 | I10: =_xlfn.XLOOKUP(H10,Store_Raw!$A$2:$A$21,Store_Raw!$B$2:$B$21) -> Alexander Group | J10: =_xlfn.XLOOKUP(H10,Store_Raw!$A$2:$A$21,Store_Raw!$C$2:$C$21) -> South | K10: =_xlfn.XLOOKUP(H10,Store_Raw!$A$2:$A$21,Store_Raw!$D$2:$D$21) -> Port Sharon | L10: =_xlfn.XLOOKUP(H10,Store_Raw!$A$2:$A$21,Store_Raw!$E$2:$E$21) -> Online | M10: =VLOOKUP(B10,Customer_Cleaned!$A$2:$H$501,2,FALSE) -> Charles Conley | N10: =VLOOKUP(B10,Customer_Cleaned!$A$2:$H$501,3,FALSE) -> 39 | O10: =VLOOKUP(B10,Customer_Cleaned!$A$2:$H$501,4,FALSE) -> Female | P10: =VLOOKUP(B10,Customer_Cleaned!$A$2:$H$501,8,FALSE) -> Silver | Q10: =_xlfn.XLOOKUP('Sales_Fact cleaned'!B387,Customer_Cleaned!$A$2:$A$501,Customer_Cleaned!$F$2:$F$501) -> Arkansas | R10: =_xlfn.XLOOKUP(B10,Customer_Cleaned!$A$2:$A$501,Customer_Cleaned!$G$2:$G$501) -> USA | S10: 1 | T10: 34.71 | U10: 0.1 | V10: 31.239 | W10: COD
A11: 45217 | B11: CUST1007 | C11: PROD5 | D11: =VLOOKUP(C11,Product_Cleaned!$A$2:$B$101,2,FALSE) -> Men's Leather Belt | E11: =VLOOKUP(C11,Product_Cleaned!$A$2:$C$101,3,FALSE) -> Clothing | F11: =VLOOKUP(C11,Product_Cleaned!$A$2:$E$101,4,FALSE) -> Accessories | G11: =VLOOKUP('Sales_Fact cleaned'!C1570,Product_Cleaned!$A$2:$E$101,5, FALSE) -> Dawson-Perkins | H11: STORE14 | I11: =_xlfn.XLOOKUP(H11,Store_Raw!$A$2:$A$21,Store_Raw!$B$2:$B$21) -> Mcdonald Inc | J11: =_xlfn.XLOOKUP(H11,Store_Raw!$A$2:$A$21,Store_Raw!$C$2:$C$21) -> South | K11: =_xlfn.XLOOKUP(H11,Store_Raw!$A$2:$A$21,Store_Raw!$D$2:$D$21) -> Christopherland | L11: =_xlfn.XLOOKUP(H11,Store_Raw!$A$2:$A$21,Store_Raw!$E$2:$E$21) -> Outlet | M11: =VLOOKUP(B11,Customer_Cleaned!$A$2:$H$501,2,FALSE) -> Daniel Boyd | N11: =VLOOKUP(B11,Customer_Cleaned!$A$2:$H$501,3,FALSE) -> 29 | O11: =VLOOKUP(B11,Customer_Cleaned!$A$2:$H$501,4,FALSE) -> Female | P11: =VLOOKUP(B11,Customer_Cleaned!$A$2:$H$501,8,FALSE) -> Bronze | Q11: =_xlfn.XLOOKUP('Sales_Fact cleaned'!B1570,Customer_Cleaned!$A$2:$A$501,Customer_Cleaned!$F$2:$F$501) -> Kansas | R11: =_xlfn.XLOOKUP(B11,Customer_Cleaned!$A$2:$A$501,Customer_Cleaned!$G$2:$G$501) -> USA | S11: 1 | T11: 38.88 | U11: 0.16 | V11: 32.6592 | W11: PayPal
A12: 45217 | B12: CUST1274 | C12: PROD44 | D12: =VLOOKUP(C12,Product_Cleaned!$A$2:$B$101,2,FALSE) -> Adjustable Jump Rope | E12: =VLOOKUP(C12,Product_Cleaned!$A$2:$C$101,3,FALSE) -> Sports | F12: =VLOOKUP(C12,Product_Cleaned!$A$2:$E$101,4,FALSE) -> Fitness | G12: =VLOOKUP('Sales_Fact cleaned'!C1379,Product_Cleaned!$A$2:$E$101,5, FALSE) -> Zhang Inc | H12: STORE4 | I12: =_xlfn.XLOOKUP(H12,Store_Raw!$A$2:$A$21,Store_Raw!$B$2:$B$21) -> Alexander Group | J12: =_xlfn.XLOOKUP(H12,Store_Raw!$A$2:$A$21,Store_Raw!$C$2:$C$21) -> South | K12: =_xlfn.XLOOKUP(H12,Store_Raw!$A$2:$A$21,Store_Raw!$D$2:$D$21) -> Port Sharon | L12: =_xlfn.XLOOKUP(H12,Store_Raw!$A$2:$A$21,Store_Raw!$E$2:$E$21) -> Online | M12: =VLOOKUP(B12,Customer_Cleaned!$A$2:$H$501,2,FALSE) -> Sarah Lane | N12: =VLOOKUP(B12,Customer_Cleaned!$A$2:$H$501,3,FALSE) -> 38 | O12: =VLOOKUP(B12,Customer_Cleaned!$A$2:$H$501,4,FALSE) -> Male | P12: =VLOOKUP(B12,Customer_Cleaned!$A$2:$H$501,8,FALSE) -> Silver | Q12: =_xlfn.XLOOKUP('Sales_Fact cleaned'!B1379,Customer_Cleaned!$A$2:$A$501,Customer_Cleaned!$F$2:$F$501) -> Georgia | R12: =_xlfn.XLOOKUP(B12,Customer_Cleaned!$A$2:$A$501,Customer_Cleaned!$G$2:$G$501) -> USA | S12: 1 | T12: 34.51 | U12: 0.04 | V12: 33.1296 | W12: PayPal
A13: 45217 | B13: CUST1305 | C13: PROD5 | D13: =VLOOKUP(C13,Product_Cleaned!$A$2:$B$101,2,FALSE) -> Men's Leather Belt | E13: =VLOOKUP(C13,Product_Cleaned!$A$2:$C$101,3,FALSE) -> Clothing | F13: =VLOOKUP(C13,Product_Cleaned!$A$2:$E$101,4,FALSE) -> Accessories | G13: =VLOOKUP('Sales_Fact cleaned'!C1442,Product_Cleaned!$A$2:$E$101,5, FALSE) -> Khan, Jones and Paul | H13: STORE4 | I13: =_xlfn.XLOOKUP(H13,Store_Raw!$A$2:$A$21,Store_Raw!$B$2:$B$21) -> Alexander Group | J13: =_xlfn.XLOOKUP(H13,Store_Raw!$A$2:$A$21,Store_Raw!$C$2:$C$21) -> South | K13: =_xlfn.XLOOKUP(H13,Store_Raw!$A$2:$A$21,Store_Raw!$D$2:$D$21) -> Port Sharon | L13: =_xlfn.XLOOKUP(H13,Store_Raw!$A$2:$A$21,Store_Raw!$E$2:$E$21) -> Online | M13: =VLOOKUP(B13,Customer_Cleaned!$A$2:$H$501,2,FALSE) -> Roberta Green | N13: =VLOOKUP(B13,Customer_Cleaned!$A$2:$H$501,3,FALSE) -> 64 | O13: =VLOOKUP(B13,Customer_Cleaned!$A$2:$H$501,4,FALSE) -> Male | P13: =VLOOKUP(B13,Customer_Cleaned!$A$2:$H$501,8,FALSE) -> Platinum | Q13: =_xlfn.XLOOKUP('Sales_Fact cleaned'!B1442,Customer_Cleaned!$A$2:$A$501,Customer_Cleaned!$F$2:$F$501) -> Kansas | R13: =_xlfn.XLOOKUP(B13,Customer_Cleaned!$A$2:$A$501,Customer_Cleaned!$G$2:$G$501) -> USA | S13: 1 | T13: 47.47 | U13: 0.28 | V13: 34.1784 | W13: PayPal
A14: 45217 | B14: CUST1095 | C14: PROD19 | D14: =VLOOKUP(C14,Product_Cleaned!$A$2:$B$101,2,FALSE) -> Knee Support Brace | E14: =VLOOKUP(C14,Product_Cleaned!$A$2:$C$101,3,FALSE) -> Sports | F14: =VLOOKUP(C14,Product_Cleaned!$A$2:$E$101,4,FALSE) -> Equipment | G14: =VLOOKUP('Sales_Fact cleaned'!C36,Product_Cleaned!$A$2:$E$101,5, FALSE) -> Campbell Ltd | H14: STORE16 | I14: =_xlfn.XLOOKUP(H14,Store_Raw!$A$2:$A$21,Store_Raw!$B$2:$B$21) -> Frederick-Wright | J14: =_xlfn.XLOOKUP(H14,Store_Raw!$A$2:$A$21,Store_Raw!$C$2:$C$21) -> West | K14: =_xlfn.XLOOKUP(H14,Store_Raw!$A$2:$A$21,Store_Raw!$D$2:$D$21) -> New Jimmymouth | L14: =_xlfn.XLOOKUP(H14,Store_Raw!$A$2:$A$21,Store_Raw!$E$2:$E$21) -> Flagship | M14: =VLOOKUP(B14,Customer_Cleaned!$A$2:$H$501,2,FALSE) -> Amy Fowler | N14: =VLOOKUP(B14,Customer_Cleaned!$A$2:$H$501,3,FALSE) -> 62 | O14: =VLOOKUP(B14,Customer_Cleaned!$A$2:$H$501,4,FALSE) -> Female | P14: =VLOOKUP(B14,Customer_Cleaned!$A$2:$H$501,8,FALSE) -> Platinum | Q14: =_xlfn.XLOOKUP('Sales_Fact cleaned'!B36,Customer_Cleaned!$A$2:$A$501,Customer_Cleaned!$F$2:$F$501) -> Tennessee | R14: =_xlfn.XLOOKUP(B14,Customer_Cleaned!$A$2:$A$501,Customer_Cleaned!$G$2:$G$501) -> USA | S14: 2 | T14: 22.47 | U14: 0.22 | V14: 35.0532 | W14: PayPal
A15: 45217 | B15: CUST1340 | C15: PROD41 | D15: =VLOOKUP(C15,Product_Cleaned!$A$2:$B$101,2,FALSE) -> Yoga Exercise Mat | E15: =VLOOKUP(C15,Product_Cleaned!$A$2:$C$101,3,FALSE) -> Sports | F15: =VLOOKUP(C15,Product_Cleaned!$A$2:$E$101,4,FALSE) -> Fitness | G15: =VLOOKUP('Sales_Fact cleaned'!C942,Product_Cleaned!$A$2:$E$101,5, FALSE) -> Stevens, Fernandez and Martin | H15: STORE5 | I15: =_xlfn.XLOOKUP(H15,Store_Raw!$A$2:$A$21,Store_Raw!$B$2:$B$21) -> Gray Ltd | J15: =_xlfn.XLOOKUP(H15,Store_Raw!$A$2:$A$21,Store_Raw!$C$2:$C$21) -> North | K15: =_xlfn.XLOOKUP(H15,Store_Raw!$A$2:$A$21,Store_Raw!$D$2:$D$21) -> New Michaelchester | L15: =_xlfn.XLOOKUP(H15,Store_Raw!$A$2:$A$21,Store_Raw!$E$2:$E$21) -> Outlet | M15: =VLOOKUP(B15,Customer_Cleaned!$A$2:$H$501,2,FALSE) -> Eric Davis | N15: =VLOOKUP(B15,Customer_Cleaned!$A$2:$H$501,3,FALSE) -> 27 | O15: =VLOOKUP(B15,Customer_Cleaned!$A$2:$H$501,4,FALSE) -> Male | P15: =VLOOKUP(B15,Customer_Cleaned!$A$2:$H$501,8,FALSE) -> Bronze | Q15: =_xlfn.XLOOKUP('Sales_Fact cleaned'!B942,Customer_Cleaned!$A$2:$A$501,Customer_Cleaned!$F$2:$F$501) -> Oregon | R15: =_xlfn.XLOOKUP(B15,Customer_Cleaned!$A$2:$A$501,Customer_Cleaned!$G$2:$G$501) -> USA | S15: 2 | T15: 20.47 | U15: 0.12 | V15: 36.0272 | W15: COD
A16: 45218 | B16: CUST1275 | C16: PROD38 | D16: =VLOOKUP(C16,Product_Cleaned!$A$2:$B$101,2,FALSE) -> Sports Water Hydration Pack | E16: =VLOOKUP(C16,Product_Cleaned!$A$2:$C$101,3,FALSE) -> Sports | F16: =VLOOKUP(C16,Product_Cleaned!$A$2:$E$101,4,FALSE) -> Outdoor | G16: =VLOOKUP('Sales_Fact cleaned'!C325,Product_Cleaned!$A$2:$E$101,5, FALSE) -> Sharp, Taylor and Rodriguez | H16: STORE9 | I16: =_xlfn.XLOOKUP(H16,Store_Raw!$A$2:$A$21,Store_Raw!$B$2:$B$21) -> Moore, Padilla and Butler | J16: =_xlfn.XLOOKUP(H16,Store_Raw!$A$2:$A$21,Store_Raw!$C$2:$C$21) -> South | K16: =_xlfn.XLOOKUP(H16,Store_Raw!$A$2:$A$21,Store_Raw!$D$2:$D$21) -> East Johnstad | L16: =_xlfn.XLOOKUP(H16,Store_Raw!$A$2:$A$21,Store_Raw!$E$2:$E$21) -> Flagship | M16: =VLOOKUP(B16,Customer_Cleaned!$A$2:$H$501,2,FALSE) -> Shannon Miller | N16: =VLOOKUP(B16,Customer_Cleaned!$A$2:$H$501,3,FALSE) -> 22 | O16: =VLOOKUP(B16,Customer_Cleaned!$A$2:$H$501,4,FALSE) -> Male | P16: =VLOOKUP(B16,Customer_Cleaned!$A$2:$H$501,8,FALSE) -> Bronze | Q16: =_xlfn.XLOOKUP('Sales_Fact cleaned'!B325,Customer_Cleaned!$A$2:$A$501,Customer_Cleaned!$F$2:$F$501) -> Iowa | R16: =_xlfn.XLOOKUP(B16,Customer_Cleaned!$A$2:$A$501,Customer_Cleaned!$G$2:$G$501) -> USA | S16: 1 | T16: 40.25 | U16: 0.1 | V16: 36.225 | W16: Credit Card
A17: 45218 | B17: CUST1490 | C17: PROD84 | D17: =VLOOKUP(C17,Product_Cleaned!$A$2:$B$101,2,FALSE) -> Wooden Bookshelf | E17: =VLOOKUP(C17,Product_Cleaned!$A$2:$C$101,3,FALSE) -> Home | F17: =VLOOKUP(C17,Product_Cleaned!$A$2:$E$101,4,FALSE) -> Furniture | G17: =VLOOKUP('Sales_Fact cleaned'!C608,Product_Cleaned!$A$2:$E$101,5, FALSE) -> Fitzpatrick Ltd | H17: STORE14 | I17: =_xlfn.XLOOKUP(H17,Store_Raw!$A$2:$A$21,Store_Raw!$B$2:$B$21) -> Mcdonald Inc | J17: =_xlfn.XLOOKUP(H17,Store_Raw!$A$2:$A$21,Store_Raw!$C$2:$C$21) -> South | K17: =_xlfn.XLOOKUP(H17,Store_Raw!$A$2:$A$21,Store_Raw!$D$2:$D$21) -> Christopherland | L17: =_xlfn.XLOOKUP(H17,Store_Raw!$A$2:$A$21,Store_Raw!$E$2:$E$21) -> Outlet | M17: =VLOOKUP(B17,Customer_Cleaned!$A$2:$H$501,2,FALSE) -> Scott Harris | N17: =VLOOKUP(B17,Customer_Cleaned!$A$2:$H$501,3,FALSE) -> 23 | O17: =VLOOKUP(B17,Customer_Cleaned!$A$2:$H$501,4,FALSE) -> Male | P17: =VLOOKUP(B17,Customer_Cleaned!$A$2:$H$501,8,FALSE) -> Bronze | Q17: =_xlfn.XLOOKUP('Sales_Fact cleaned'!B608,Customer_Cleaned!$A$2:$A$501,Customer_Cleaned!$F$2:$F$501) -> Minnesota | R17: =_xlfn.XLOOKUP(B17,Customer_Cleaned!$A$2:$A$501,Customer_Cleaned!$G$2:$G$501) -> USA | S17: 1 | T17: 46.66 | U17: 0.2 | V17: 37.328 | W17: COD
A18: 45219 | B18: CUST1431 | C18: PROD25 | D18: =VLOOKUP(C18,Product_Cleaned!$A$2:$B$101,2,FALSE) -> Women's Scarf Set | E18: =VLOOKUP(C18,Product_Cleaned!$A$2:$C$101,3,FALSE) -> Clothing | F18: =VLOOKUP(C18,Product_Cleaned!$A$2:$E$101,4,FALSE) -> Accessories | G18: =VLOOKUP('Sales_Fact cleaned'!C97,Product_Cleaned!$A$2:$E$101,5, FALSE) -> Lopez LLC | H18: STORE8 | I18: =_xlfn.XLOOKUP(H18,Store_Raw!$A$2:$A$21,Store_Raw!$B$2:$B$21) -> Bean, Jones and Park | J18: =_xlfn.XLOOKUP(H18,Store_Raw!$A$2:$A$21,Store_Raw!$C$2:$C$21) -> West | K18: =_xlfn.XLOOKUP(H18,Store_Raw!$A$2:$A$21,Store_Raw!$D$2:$D$21) -> Thompsonborough | L18: =_xlfn.XLOOKUP(H18,Store_Raw!$A$2:$A$21,Store_Raw!$E$2:$E$21) -> Online | M18: =VLOOKUP(B18,Customer_Cleaned!$A$2:$H$501,2,FALSE) -> John Smith | N18: =VLOOKUP(B18,Customer_Cleaned!$A$2:$H$501,3,FALSE) -> 27 | O18: =VLOOKUP(B18,Customer_Cleaned!$A$2:$H$501,4,FALSE) -> Male | P18: =VLOOKUP(B18,Customer_Cleaned!$A$2:$H$501,8,FALSE) -> Bronze | Q18: =_xlfn.XLOOKUP('Sales_Fact cleaned'!B97,Customer_Cleaned!$A$2:$A$501,Customer_Cleaned!$F$2:$F$501) -> New Jersey | R18: =_xlfn.XLOOKUP(B18,Customer_Cleaned!$A$2:$A$501,Customer_Cleaned!$G$2:$G$501) -> USA | S18: 1 | T18: 52.06 | U18: 0.27 | V18: 38.0038 | W18: PayPal
A19: 45219 | B19: CUST1003 | C19: PROD74 | D19: =VLOOKUP(C19,Product_Cleaned!$A$2:$B$101,2,FALSE) -> Bluetooth Car Audio System | E19: =VLOOKUP(C19,Product_Cleaned!$A$2:$C$101,3,FALSE) -> Electronics | F19: =VLOOKUP(C19,Product_Cleaned!$A$2:$E$101,4,FALSE) -> Audio | G19: =VLOOKUP('Sales_Fact cleaned'!C1335,Product_Cleaned!$A$2:$E$101,5, FALSE) -> Bridges, Banks and Cummings | H19: STORE15 | I19: =_xlfn.XLOOKUP(H19,Store_Raw!$A$2:$A$21,Store_Raw!$B$2:$B$21) -> Shelton PLC | J19: =_xlfn.XLOOKUP(H19,Store_Raw!$A$2:$A$21,Store_Raw!$C$2:$C$21) -> North | K19: =_xlfn.XLOOKUP(H19,Store_Raw!$A$2:$A$21,Store_Raw!$D$2:$D$21) -> East Jenniferstad | L19: =_xlfn.XLOOKUP(H19,Store_Raw!$A$2:$A$21,Store_Raw!$E$2:$E$21) -> Flagship | M19: =VLOOKUP(B19,Customer_Cleaned!$A$2:$H$501,2,FALSE) -> Jeremy Harris | N19: =VLOOKUP(B19,Customer_Cleaned!$A$2:$H$501,3,FALSE) -> 59 | O19: =VLOOKUP(B19,Customer_Cleaned!$A$2:$H$501,4,FALSE) -> Female | P19: =VLOOKUP(B19,Customer_Cleaned!$A$2:$H$501,8,FALSE) -> Platinum | Q19: =_xlfn.XLOOKUP('Sales_Fact cleaned'!B1335,Customer_Cleaned!$A$2:$A$501,Customer_Cleaned!$F$2:$F$501) -> Oregon | R19: =_xlfn.XLOOKUP(B19,Customer_Cleaned!$A$2:$A$501,Customer_Cleaned!$G$2:$G$501) -> USA | S19: 2 | T19: 25.3 | U19: 0.21 | V19: 39.974 | W19: Credit Card
A20: 45220 | B20: CUST1249 | C20: PROD72 | D20: =VLOOKUP(C20,Product_Cleaned!$A$2:$B$101,2,FALSE) -> Professional Jump Rope | E20: =VLOOKUP(C20,Product_Cleaned!$A$2:$C$101,3,FALSE) -> Sports | F20: =VLOOKUP(C20,Product_Cleaned!$A$2:$E$101,4,FALSE) -> Fitness | G20: =VLOOKUP('Sales_Fact cleaned'!C1645,Product_Cleaned!$A$2:$E$101,5, FALSE) -> Weiss-Watson | H20: STORE4 | I20: =_xlfn.XLOOKUP(H20,Store_Raw!$A$2:$A$21,Store_Raw!$B$2:$B$21) -> Alexander Group | J20: =_xlfn.XLOOKUP(H20,Store_Raw!$A$2:$A$21,Store_Raw!$C$2:$C$21) -> South | K20: =_xlfn.XLOOKUP(H20,Store_Raw!$A$2:$A$21,Store_Raw!$D$2:$D$21) -> Port Sharon | L20: =_xlfn.XLOOKUP(H20,Store_Raw!$A$2:$A$21,Store_Raw!$E$2:$E$21) -> Online | M20: =VLOOKUP(B20,Customer_Cleaned!$A$2:$H$501,2,FALSE) -> Lauren George | N20: =VLOOKUP(B20,Customer_Cleaned!$A$2:$H$501,3,FALSE) -> 41 | O20: =VLOOKUP(B20,Customer_Cleaned!$A$2:$H$501,4,FALSE) -> Female | P20: =VLOOKUP(B20,Customer_Cleaned!$A$2:$H$501,8,FALSE) -> Silver | Q20: =_xlfn.XLOOKUP('Sales_Fact cleaned'!B1645,Customer_Cleaned!$A$2:$A$501,Customer_Cleaned!$F$2:$F$501) -> Indiana | R20: =_xlfn.XLOOKUP(B20,Customer_Cleaned!$A$2:$A$501,Customer_Cleaned!$G$2:$G$501) -> USA | S20: 1 | T20: 41.39 | U20: 0.01 | V20: 40.9761 | W20: COD
A21: 45220 | B21: CUST1425 | C21: PROD72 | D21: =VLOOKUP(C21,Product_Cleaned!$A$2:$B$101,2,FALSE) -> Professional Jump Rope | E21: =VLOOKUP(C21,Product_Cleaned!$A$2:$C$101,3,FALSE) -> Sports | F21: =VLOOKUP(C21,Product_Cleaned!$A$2:$E$101,4,FALSE) -> Fitness | G21: =VLOOKUP('Sales_Fact cleaned'!C514,Product_Cleaned!$A$2:$E$101,5, FALSE) -> Bruce-Bowen | H21: STORE19 | I21: =_xlfn.XLOOKUP(H21,Store_Raw!$A$2:$A$21,Store_Raw!$B$2:$B$21) -> Mann-Austin | J21: =_xlfn.XLOOKUP(H21,Store_Raw!$A$2:$A$21,Store_Raw!$C$2:$C$21) -> East | K21: =_xlfn.XLOOKUP(H21,Store_Raw!$A$2:$A$21,Store_Raw!$D$2:$D$21) -> Vasquezborough | L21: =_xlfn.XLOOKUP(H21,Store_Raw!$A$2:$A$21,Store_Raw!$E$2:$E$21) -> Online | M21: =VLOOKUP(B21,Customer_Cleaned!$A$2:$H$501,2,FALSE) -> Bryce Hawkins | N21: =VLOOKUP(B21,Customer_Cleaned!$A$2:$H$501,3,FALSE) -> 40 | O21: =VLOOKUP(B21,Customer_Cleaned!$A$2:$H$501,4,FALSE) -> Male | P21: =VLOOKUP(B21,Customer_Cleaned!$A$2:$H$501,8,FALSE) -> Silver | Q21: =_xlfn.XLOOKUP('Sales_Fact cleaned'!B514,Customer_Cleaned!$A$2:$A$501,Customer_Cleaned!$F$2:$F$501) -> Vermont | R21: =_xlfn.XLOOKUP(B21,Customer_Cleaned!$A$2:$A$501,Customer_Cleaned!$G$2:$G$501) -> USA | S21: 1 | T21: 44.08 | U21: 0.05 | V21: 41.876 | W21: Credit Card
A22: 45221 | B22: CUST1137 | C22: PROD8 | D22: =VLOOKUP(C22,Product_Cleaned!$A$2:$B$101,2,FALSE) -> Wireless Bluetooth Earbuds | E22: =VLOOKUP(C22,Product_Cleaned!$A$2:$C$101,3,FALSE) -> Electronics | F22: =VLOOKUP(C22,Product_Cleaned!$A$2:$E$101,4,FALSE) -> Audio | G22: =VLOOKUP('Sales_Fact cleaned'!C269,Product_Cleaned!$A$2:$E$101,5, FALSE) -> Brown and Sons | H22: STORE15 | I22: =_xlfn.XLOOKUP(H22,Store_Raw!$A$2:$A$21,Store_Raw!$B$2:$B$21) -> Shelton PLC | J22: =_xlfn.XLOOKUP(H22,Store_Raw!$A$2:$A$21,Store_Raw!$C$2:$C$21) -> North | K22: =_xlfn.XLOOKUP(H22,Store_Raw!$A$2:$A$21,Store_Raw!$D$2:$D$21) -> East Jenniferstad | L22: =_xlfn.XLOOKUP(H22,Store_Raw!$A$2:$A$21,Store_Raw!$E$2:$E$21) -> Flagship | M22: =VLOOKUP(B22,Customer_Cleaned!$A$2:$H$501,2,FALSE) -> Rick Dominguez | N22: =VLOOKUP(B22,Customer_Cleaned!$A$2:$H$501,3,FALSE) -> 55 | O22: =VLOOKUP(B22,Customer_Cleaned!$A$2:$H$501,4,FALSE) -> Female | P22: =VLOOKUP(B22,Customer_Cleaned!$A$2:$H$501,8,FALSE) -> Platinum | Q22: =_xlfn.XLOOKUP('Sales_Fact cleaned'!B269,Customer_Cleaned!$A$2:$A$501,Customer_Cleaned!$F$2:$F$501) -> Kansas | R22: =_xlfn.XLOOKUP(B22,Customer_Cleaned!$A$2:$A$501,Customer_Cleaned!$G$2:$G$501) -> USA | S22: 1 | T22: 43.58 | U22: 0.01 | V22: 43.1442 | W22: COD
A23: 45222 | B23: CUST1036 | C23: PROD59 | D23: =VLOOKUP(C23,Product_Cleaned!$A$2:$B$101,2,FALSE) -> Men's Hair Styling Gel | E23: =VLOOKUP(C23,Product_Cleaned!$A$2:$C$101,3,FALSE) -> Beauty | F23: =VLOOKUP(C23,Product_Cleaned!$A$2:$E$101,4,FALSE) -> Haircare | G23: =VLOOKUP('Sales_Fact cleaned'!C594,Product_Cleaned!$A$2:$E$101,5, FALSE) -> Wilson Group | H23: STORE11 | I23: =_xlfn.XLOOKUP(H23,Store_Raw!$A$2:$A$21,Store_Raw!$B$2:$B$21) -> Aguirre-Keller | J23: =_xlfn.XLOOKUP(H23,Store_Raw!$A$2:$A$21,Store_Raw!$C$2:$C$21) -> South | K23: =_xlfn.XLOOKUP(H23,Store_Raw!$A$2:$A$21,Store_Raw!$D$2:$D$21) -> Lake Michael | L23: =_xlfn.XLOOKUP(H23,Store_Raw!$A$2:$A$21,Store_Raw!$E$2:$E$21) -> Online | M23: =VLOOKUP(B23,Customer_Cleaned!$A$2:$H$501,2,FALSE) -> Thomas Phillips | N23: =VLOOKUP(B23,Customer_Cleaned!$A$2:$H$501,3,FALSE) -> 20 | O23: =VLOOKUP(B23,Customer_Cleaned!$A$2:$H$501,4,FALSE) -> Female | P23: =VLOOKUP(B23,Customer_Cleaned!$A$2:$H$501,8,FALSE) -> Bronze | Q23: =_xlfn.XLOOKUP('Sales_Fact cleaned'!B594,Customer_Cleaned!$A$2:$A$501,Customer_Cleaned!$F$2:$F$501) -> South Carolina | R23: =_xlfn.XLOOKUP(B23,Customer_Cleaned!$A$2:$A$501,Customer_Cleaned!$G$2:$G$501) -> USA | S23: 2 | T23: 23.58 | U23: 0.02 | V23: 46.2168 | W23: PayPal
A24: 45222 | B24: CUST1207 | C24: PROD84 | D24: =VLOOKUP(C24,Product_Cleaned!$A$2:$B$101,2,FALSE) -> Wooden Bookshelf | E24: =VLOOKUP(C24,Product_Cleaned!$A$2:$C$101,3,FALSE) -> Home | F24: =VLOOKUP(C24,Product_Cleaned!$A$2:$E$101,4,FALSE) -> Furniture | G24: =VLOOKUP('Sales_Fact cleaned'!C1947,Product_Cleaned!$A$2:$E$101,5, FALSE) -> Hatfield, Baird and Torres | H24: STORE8 | I24: =_xlfn.XLOOKUP(H24,Store_Raw!$A$2:$A$21,Store_Raw!$B$2:$B$21) -> Bean, Jones and Park | J24: =_xlfn.XLOOKUP(H24,Store_Raw!$A$2:$A$21,Store_Raw!$C$2:$C$21) -> West | K24: =_xlfn.XLOOKUP(H24,Store_Raw!$A$2:$A$21,Store_Raw!$D$2:$D$21) -> Thompsonborough | L24: =_xlfn.XLOOKUP(H24,Store_Raw!$A$2:$A$21,Store_Raw!$E$2:$E$21) -> Online | M24: =VLOOKUP(B24,Customer_Cleaned!$A$2:$H$501,2,FALSE) -> Jacqueline Pacheco | N24: =VLOOKUP(B24,Customer_Cleaned!$A$2:$H$501,3,FALSE) -> 28 | O24: =VLOOKUP(B24,Customer_Cleaned!$A$2:$H$501,4,FALSE) -> Female | P24: =VLOOKUP(B24,Customer_Cleaned!$A$2:$H$501,8,FALSE) -> Bronze | Q24: =_xlfn.XLOOKUP('Sales_Fact cleaned'!B1947,Customer_Cleaned!$A$2:$A$501,Customer_Cleaned!$F$2:$F$501) -> Washington | R24: =_xlfn.XLOOKUP(B24,Customer_Cleaned!$A$2:$A$501,Customer_Cleaned!$G$2:$G$501) -> USA | S24: 2 | T24: 30.14 | U24: 0.21 | V24: 47.6212 | W24: PayPal
A25: 45222 | B25: CUST1172 | C25: PROD11 | D25: =VLOOKUP(C25,Product_Cleaned!$A$2:$B$101,2,FALSE) -> HD Smart TV Stick | E25: =VLOOKUP(C25,Product_Cleaned!$A$2:$C$101,3,FALSE) -> Electronics | F25: =VLOOKUP(C25,Product_Cleaned!$A$2:$E$101,4,FALSE) -> Accessories | G25: =VLOOKUP('Sales_Fact cleaned'!C1623,Product_Cleaned!$A$2:$E$101,5, FALSE) -> Hoffman-Williams | H25: STORE6 | I25: =_xlfn.XLOOKUP(H25,Store_Raw!$A$2:$A$21,Store_Raw!$B$2:$B$21) -> Benson-Elliott | J25: =_xlfn.XLOOKUP(H25,Store_Raw!$A$2:$A$21,Store_Raw!$C$2:$C$21) -> East | K25: =_xlfn.XLOOKUP(H25,Store_Raw!$A$2:$A$21,Store_Raw!$D$2:$D$21) -> Port Josephberg | L25: =_xlfn.XLOOKUP(H25,Store_Raw!$A$2:$A$21,Store_Raw!$E$2:$E$21) -> Online | M25: =VLOOKUP(B25,Customer_Cleaned!$A$2:$H$501,2,FALSE) -> Thomas Rhodes | N25: =VLOOKUP(B25,Customer_Cleaned!$A$2:$H$501,3,FALSE) -> 41 | O25: =VLOOKUP(B25,Customer_Cleaned!$A$2:$H$501,4,FALSE) -> Female | P25: =VLOOKUP(B25,Customer_Cleaned!$A$2:$H$501,8,FALSE) -> Silver | Q25: =_xlfn.XLOOKUP('Sales_Fact cleaned'!B1623,Customer_Cleaned!$A$2:$A$501,Customer_Cleaned!$F$2:$F$501) -> Iowa | R25: =_xlfn.XLOOKUP(B25,Customer_Cleaned!$A$2:$A$501,Customer_Cleaned!$G$2:$G$501) -> USA | S25: 1 | T25: 56.59 | U25: 0.15 | V25: 48.1015 | W25: Credit Card
A26: 45222 | B26: CUST1463 | C26: PROD31 | D26: =VLOOKUP(C26,Product_Cleaned!$A$2:$B$101,2,FALSE) -> Basketball | E26: =VLOOKUP(C26,Product_Cleaned!$A$2:$C$101,3,FALSE) -> Sports | F26: =VLOOKUP(C26,Product_Cleaned!$A$2:$E$101,4,FALSE) -> Team Sports | G26: =VLOOKUP('Sales_Fact cleaned'!C1455,Product_Cleaned!$A$2:$E$101,5, FALSE) -> Guerra-Hendrix | H26: STORE15 | I26: =_xlfn.XLOOKUP(H26,Store_Raw!$A$2:$A$21,Store_Raw!$B$2:$B$21) -> Shelton PLC | J26: =_xlfn.XLOOKUP(H26,Store_Raw!$A$2:$A$21,Store_Raw!$C$2:$C$21) -> North | K26: =_xlfn.XLOOKUP(H26,Store_Raw!$A$2:$A$21,Store_Raw!$D$2:$D$21) -> East Jenniferstad | L26: =_xlfn.XLOOKUP(H26,Store_Raw!$A$2:$A$21,Store_Raw!$E$2:$E$21) -> Flagship | M26: =VLOOKUP(B26,Customer_Cleaned!$A$2:$H$501,2,FALSE) -> Samantha Lee | N26: =VLOOKUP(B26,Customer_Cleaned!$A$2:$H$501,3,FALSE) -> 36 | O26: =VLOOKUP(B26,Customer_Cleaned!$A$2:$H$501,4,FALSE) -> Female | P26: =VLOOKUP(B26,Customer_Cleaned!$A$2:$H$501,8,FALSE) -> Silver | Q26: =_xlfn.XLOOKUP('Sales_Fact cleaned'!B1455,Customer_Cleaned!$A$2:$A$501,Customer_Cleaned!$F$2:$F$501) -> Pennsylvania | R26: =_xlfn.XLOOKUP(B26,Customer_Cleaned!$A$2:$A$501,Customer_Cleaned!$G$2:$G$501) -> USA | S26: 2 | T26: 31.28 | U26: 0.2 | V26: 50.048 | W26: COD
A27: 45223 | B27: CUST1092 | C27: PROD10 | D27: =VLOOKUP(C27,Product_Cleaned!$A$2:$B$101,2,FALSE) -> Ceramic Kitchen Bowl Set | E27: =VLOOKUP(C27,Product_Cleaned!$A$2:$C$101,3,FALSE) -> Home | F27: =VLOOKUP(C27,Product_Cleaned!$A$2:$E$101,4,FALSE) -> Kitchen | G27: =VLOOKUP('Sales_Fact cleaned'!C663,Product_Cleaned!$A$2:$E$101,5, FALSE) -> Torres, Spencer and Potter | H27: STORE11 | I27: =_xlfn.XLOOKUP(H27,Store_Raw!$A$2:$A$21,Store_Raw!$B$2:$B$21) -> Aguirre-Keller | J27: =_xlfn.XLOOKUP(H27,Store_Raw!$A$2:$A$21,Store_Raw!$C$2:$C$21) -> South | K27: =_xlfn.XLOOKUP(H27,Store_Raw!$A$2:$A$21,Store_Raw!$D$2:$D$21) -> Lake Michael | L27: =_xlfn.XLOOKUP(H27,Store_Raw!$A$2:$A$21,Store_Raw!$E$2:$E$21) -> Online | M27: =VLOOKUP(B27,Customer_Cleaned!$A$2:$H$501,2,FALSE) -> Robert Jackson | N27: =VLOOKUP(B27,Customer_Cleaned!$A$2:$H$501,3,FALSE) -> 44 | O27: =VLOOKUP(B27,Customer_Cleaned!$A$2:$H$501,4,FALSE) -> Female | P27: =VLOOKUP(B27,Customer_Cleaned!$A$2:$H$501,8,FALSE) -> Silver | Q27: =_xlfn.XLOOKUP('Sales_Fact cleaned'!B663,Customer_Cleaned!$A$2:$A$501,Customer_Cleaned!$F$2:$F$501) -> Vermont | R27: =_xlfn.XLOOKUP(B27,Customer_Cleaned!$A$2:$A$501,Customer_Cleaned!$G$2:$G$501) -> USA | S27: 1 | T27: 57.94 | U27: 0.13 | V27: 50.4078 | W27: Credit Card
A28: 45223 | B28: CUST1030 | C28: PROD40 | D28: =VLOOKUP(C28,Product_Cleaned!$A$2:$B$101,2,FALSE) -> Noise-Canceling Headphones | E28: =VLOOKUP(C28,Product_Cleaned!$A$2:$C$101,3,FALSE) -> Electronics | F28: =VLOOKUP(C28,Product_Cleaned!$A$2:$E$101,4,FALSE) -> Audio | G28: =VLOOKUP('Sales_Fact cleaned'!C576,Product_Cleaned!$A$2:$E$101,5, FALSE) -> Atkinson, Camacho and Oliver | H28: STORE9 | I28: =_xlfn.XLOOKUP(H28,Store_Raw!$A$2:$A$21,Store_Raw!$B$2:$B$21) -> Moore, Padilla and Butler | J28: =_xlfn.XLOOKUP(H28,Store_Raw!$A$2:$A$21,Store_Raw!$C$2:$C$21) -> South | K28: =_xlfn.XLOOKUP(H28,Store_Raw!$A$2:$A$21,Store_Raw!$D$2:$D$21) -> East Johnstad | L28: =_xlfn.XLOOKUP(H28,Store_Raw!$A$2:$A$21,Store_Raw!$E$2:$E$21) -> Flagship | M28: =VLOOKUP(B28,Customer_Cleaned!$A$2:$H$501,2,FALSE) -> Jessica Acevedo | N28: =VLOOKUP(B28,Customer_Cleaned!$A$2:$H$501,3,FALSE) -> 64 | O28: =VLOOKUP(B28,Customer_Cleaned!$A$2:$H$501,4,FALSE) -> Female | P28: =VLOOKUP(B28,Customer_Cleaned!$A$2:$H$501,8,FALSE) -> Platinum | Q28: =_xlfn.XLOOKUP('Sales_Fact cleaned'!B576,Customer_Cleaned!$A$2:$A$501,Customer_Cleaned!$F$2:$F$501) -> Minnesota | R28: =_xlfn.XLOOKUP(B28,Customer_Cleaned!$A$2:$A$501,Customer_Cleaned!$G$2:$G$501) -> USA | S28: 2 | T28: 26.36 | U28: 0.03 | V28: 51.1384 | W28: COD
A29: 45223 | B29: CUST1223 | C29: PROD81 | D29: =VLOOKUP(C29,Product_Cleaned!$A$2:$B$101,2,FALSE) -> Badminton Racket Set | E29: =VLOOKUP(C29,Product_Cleaned!$A$2:$C$101,3,FALSE) -> Sports | F29: =VLOOKUP(C29,Product_Cleaned!$A$2:$E$101,4,FALSE) -> Equipment | G29: =VLOOKUP('Sales_Fact cleaned'!C1193,Product_Cleaned!$A$2:$E$101,5, FALSE) -> Hoffman Group | H29: STORE12 | I29: =_xlfn.XLOOKUP(H29,Store_Raw!$A$2:$A$21,Store_Raw!$B$2:$B$21) -> Thomas, Bridges and Harris | J29: =_xlfn.XLOOKUP(H29,Store_Raw!$A$2:$A$21,Store_Raw!$C$2:$C$21) -> North | K29: =_xlfn.XLOOKUP(H29,Store_Raw!$A$2:$A$21,Store_Raw!$D$2:$D$21) -> Sabrinatown | L29: =_xlfn.XLOOKUP(H29,Store_Raw!$A$2:$A$21,Store_Raw!$E$2:$E$21) -> Online | M29: =VLOOKUP(B29,Customer_Cleaned!$A$2:$H$501,2,FALSE) -> Robert Harris | N29: =VLOOKUP(B29,Customer_Cleaned!$A$2:$H$501,3,FALSE) -> 50 | O29: =VLOOKUP(B29,Customer_Cleaned!$A$2:$H$501,4,FALSE) -> Male | P29: =VLOOKUP(B29,Customer_Cleaned!$A$2:$H$501,8,FALSE) -> Platinum | Q29: =_xlfn.XLOOKUP('Sales_Fact cleaned'!B1193,Customer_Cleaned!$A$2:$A$501,Customer_Cleaned!$F$2:$F$501) -> Massachusetts | R29: =_xlfn.XLOOKUP(B29,Customer_Cleaned!$A$2:$A$501,Customer_Cleaned!$G$2:$G$501) -> USA | S29: 1 | T29: 64.94 | U29: 0.21 | V29: 51.3026 | W29: Credit Card
